<mujoco model="g1_dual_arm">
  <compiler angle="radian" meshdir="assets"/>
  <include file="../object_manipulation/cube.xml"/>

  <asset>
    <mesh name="waist_yaw_link" file="waist_yaw_link.STL"/>
    <mesh name="waist_roll_link" file="waist_roll_link.STL"/>
    <mesh name="torso_link" file="torso_link.STL"/>
    <mesh name="logo_link" file="logo_link.STL"/>
    <mesh name="head_link" file="head_link.STL"/>
    <mesh name="waist_support_link" file="waist_support_link.STL"/>
    <mesh name="left_shoulder_pitch_link" file="left_shoulder_pitch_link.STL"/>
    <mesh name="left_shoulder_roll_link" file="left_shoulder_roll_link.STL"/>
    <mesh name="left_shoulder_yaw_link" file="left_shoulder_yaw_link.STL"/>
    <mesh name="left_elbow_link" file="left_elbow_link.STL"/>
    <mesh name="left_wrist_roll_link" file="left_wrist_roll_link.STL"/>
    <mesh name="left_wrist_pitch_link" file="left_wrist_pitch_link.STL"/>
    <mesh name="left_wrist_yaw_link" file="left_wrist_yaw_link.STL"/>
    <mesh name="left_rubber_hand" file="left_rubber_hand.STL"/>
    <mesh name="right_shoulder_pitch_link" file="right_shoulder_pitch_link.STL"/>
    <mesh name="right_shoulder_roll_link" file="right_shoulder_roll_link.STL"/>
    <mesh name="right_shoulder_yaw_link" file="right_shoulder_yaw_link.STL"/>
    <mesh name="right_elbow_link" file="right_elbow_link.STL"/>
    <mesh name="right_wrist_roll_link" file="right_wrist_roll_link.STL"/>
    <mesh name="right_wrist_pitch_link" file="right_wrist_pitch_link.STL"/>
    <mesh name="right_wrist_yaw_link" file="right_wrist_yaw_link.STL"/>
    <mesh name="right_rubber_hand" file="right_rubber_hand.STL"/>
    <material name="black" specular="0.5" shininess="0.25" rgba="0.16355 0.16355 0.16355 1"/>
    <material name="gray" specular="0.0" shininess="0.25" rgba="0.80848 0.80848 0.80848 1"/>
    <material name="metallic" specular="0" shininess="0.25" rgba="0.9 0.9 0.9 1"/>

    <mesh class="left_hand" file="forearm_0.obj"/>
    <mesh class="left_hand" file="forearm_1.obj"/>
    <mesh class="left_hand" file="forearm_collision.obj"/>
    <mesh class="left_hand" file="wrist.obj" scale="-0.001 0.001 0.001"/>
    <mesh class="left_hand" file="palm.obj" scale="-0.001 0.001 0.001"/>
    <mesh class="left_hand" file="f_knuckle.obj"/>
    <mesh class="left_hand" file="f_proximal.obj"/>
    <mesh class="left_hand" file="f_middle.obj"/>
    <mesh class="left_hand" file="f_distal_pst.obj"/>
    <mesh class="left_hand" file="lf_metacarpal.obj" scale="-0.001 0.001 0.001"/>
    <mesh class="left_hand" file="th_proximal.obj"/>
    <mesh class="left_hand" file="th_middle.obj"/>
    <mesh class="left_hand" file="th_distal_pst.obj"/>
  </asset>

  <!-- Actuator default classes for control parameters -->
  <default>
    <default class="arm_joint">
      <position kp="5" ctrlrange="-2 2" forcerange="-25 25"/>
    </default>
  </default>
  <default >
    <default class="left_hand">
      <mesh scale="0.001 0.001 0.001"/>
      <joint axis="1 0 0" damping="0.05" armature="0.0002" frictionloss="0.01"/>
      <position forcerange="-1 1"/>

      <default class="wrist">
        
        <default class="wrist_x">
          <joint range="-0.698132 0.488692"/>
          <position kp="8" ctrlrange="-0.698132 0.488692" forcerange="-5 5"/>
        </default>
      </default>

      <default class="thumb">
        <default class="thbase">
          <joint axis="0 0 1" range="-1.0472 1.0472"/>
          <position kp="0.4" ctrlrange="-1.0472 1.0472" forcerange="-3 3"/>
        </default>
        <default class="thproximal">
          <joint axis="-1 0 0" range="0 1.22173"/>
          <position ctrlrange="0 1.22173" forcerange="-2 2"/>
        </default>
        <default class="thhub">
          <joint axis="-1 0 0" range="-0.20944 0.20944"/>
          <position kp="0.5" ctrlrange="-0.20944 0.20944"/>
        </default>
        <default class="thmiddle">
          <joint axis="0 -1 0" range="-0.698132 0.698132"/>
          <position kp="1.5" ctrlrange="-0.698132 0.698132"/>
        </default>
        <default class="thdistal">
          <joint range="-0.261799 1.5708"/>
          <position ctrlrange="-0.261799 1.5708"/>
        </default>
      </default>

      <default class="metacarpal">
        <joint axis="0.573576 0 0.819152" range="0 0.785398"/>
        <position ctrlrange="0 0.785398"/>
      </default>
      <default class="knuckle">
        <joint axis="0 -1 0" range="-0.349066 0.349066"/>
        <position ctrlrange="-0.349066 0.349066"/>
      </default>
      <default class="proximal">
        <joint range="-0.261799 1.5708"/>
        <position ctrlrange="-0.261799 1.5708"/>
      </default>
      <default class="middle_distal">
        <joint range="0 1.5708"/>
        <position kp="0.5" ctrlrange="0 3.1415"/>
      </default>

      <default class="plastic">
        <geom solimp="0.5 0.99 0.0001" solref="0.005 1"/>
        <default class="plastic_visual">
          <geom type="mesh" material="black" contype="0" conaffinity="0" group="2"/>
        </default>
        <default class="plastic_collision">
          <geom group="3"/>
        </default>
      </default>
    </default>
  </default>

  <worldbody>
    <geom type="mesh" contype="0" conaffinity="0" group="1" density="0" rgba="0.7 0.7 0.7 1" mesh="waist_yaw_link"/>
    <geom pos="-0.0039635 0 0.035" type="mesh" contype="0" conaffinity="0" group="1" density="0" rgba="0.7 0.7 0.7 1" mesh="waist_roll_link"/>
    <geom pos="-0.0039635 0 0.054" type="mesh" contype="0" conaffinity="0" group="1" density="0" rgba="0.7 0.7 0.7 1" mesh="torso_link"/>
    <geom pos="-0.0039635 0 0.054" type="mesh" rgba="0.7 0.7 0.7 1" mesh="torso_link"/>
    <geom type="mesh" contype="0" conaffinity="0" group="1" density="0" rgba="0.2 0.2 0.2 1" mesh="logo_link"/>
    <geom type="mesh" rgba="0.2 0.2 0.2 1" mesh="logo_link"/>
    <geom type="mesh" contype="0" conaffinity="0" group="1" density="0" rgba="0.2 0.2 0.2 1" mesh="head_link"/>
    <geom type="mesh" rgba="0.2 0.2 0.2 1" mesh="head_link"/>
    <geom type="mesh" contype="0" conaffinity="0" group="1" density="0" rgba="0.7 0.7 0.7 1" mesh="waist_support_link"/>
    <geom type="mesh" rgba="0.7 0.7 0.7 1" mesh="waist_support_link"/>

    <body name="left_shoulder_pitch_link" pos="-7.2e-06 0.10022 0.29178" quat="0.990264 0.139201 1.38722e-05 -9.86868e-05">
      <inertial pos="0 0.035892 -0.011628" quat="0.654152 0.0130458 -0.326267 0.68225" mass="0.718" diaginertia="0.000465864 0.000432842 0.000406394"/>
      <joint name="left_shoulder_pitch_joint" pos="0 0 0" axis="0 1 0" range="-3.0892 2.6704" actuatorfrcrange="-25 25"/>
      <geom type="mesh" contype="0" conaffinity="0" group="1" density="0" rgba="0.7 0.7 0.7 1" mesh="left_shoulder_pitch_link"/>
      <geom size="0.03 0.025" pos="0 0.04 -0.01" quat="0.707107 0 0.707107 0" type="cylinder" rgba="0.7 0.7 0.7 1"/>
      <body name="left_shoulder_roll_link" pos="0 0.038 -0.013831" quat="0.990268 -0.139172 0 0">
        <inertial pos="-0.000227 0.00727 -0.063243" quat="0.701256 -0.0196223 -0.00710317 0.712604" mass="0.643" diaginertia="0.000691311 0.000618011 0.000388977"/>
        <joint name="left_shoulder_roll_joint" pos="0 0 0" axis="1 0 0" range="-1.5882 2.2515" actuatorfrcrange="-25 25"/>
        <geom type="mesh" contype="0" conaffinity="0" group="1" density="0" rgba="0.7 0.7 0.7 1" mesh="left_shoulder_roll_link"/>
        <geom size="0.03 0.015" pos="-0.004 0.006 -0.053" type="cylinder" rgba="0.7 0.7 0.7 1"/>
        <body name="left_shoulder_yaw_link" pos="0 0.00624 -0.1032">
          <inertial pos="0.010773 -0.002949 -0.072009" quat="0.716879 -0.0964829 -0.0679942 0.687134" mass="0.734" diaginertia="0.00106187 0.00103217 0.000400661"/>
          <joint name="left_shoulder_yaw_joint" pos="0 0 0" axis="0 0 1" range="-2.618 2.618" actuatorfrcrange="-25 25"/>
          <geom type="mesh" contype="0" conaffinity="0" group="1" density="0" rgba="0.7 0.7 0.7 1" mesh="left_shoulder_yaw_link"/>
          <geom type="mesh" rgba="0.7 0.7 0.7 1" mesh="left_shoulder_yaw_link"/>
          <body name="left_elbow_link" pos="0.015783 0 -0.080518">
            <inertial pos="0.064956 0.004454 -0.010062" quat="0.541765 0.636132 0.388821 0.388129" mass="0.6" diaginertia="0.000443035 0.000421612 0.000259353"/>
            <joint name="left_elbow_joint" pos="0 0 0" axis="0 1 0" range="-1.0472 2.0944" actuatorfrcrange="-25 25"/>
            <geom type="mesh" contype="0" conaffinity="0" group="1" density="0" rgba="0.7 0.7 0.7 1" mesh="left_elbow_link"/>
            <geom type="mesh" rgba="0.7 0.7 0.7 1" mesh="left_elbow_link"/>
            <body name="left_wrist_roll_link" pos="0.1 0.00188791 -0.01">
              <inertial pos="0.0171394 0.000537591 4.8864e-07" quat="0.575338 0.411667 -0.574906 0.411094" mass="0.085445" diaginertia="5.48211e-05 4.96646e-05 3.57798e-05"/>
              <joint name="left_wrist_roll_joint" pos="0 0 0" axis="1 0 0" range="-1.97222 1.97222" actuatorfrcrange="-25 25"/>
              <geom type="mesh" contype="0" conaffinity="0" group="1" density="0" rgba="0.7 0.7 0.7 1" mesh="left_wrist_roll_link"/>
              <geom type="mesh" rgba="0.7 0.7 0.7 1" mesh="left_wrist_roll_link"/>
              <body name="left_wrist_pitch_link" pos="0.038 0 0">
                <inertial pos="0.0229999 -0.00111685 -0.00111658" quat="0.249998 0.661363 0.293036 0.643608" mass="0.48405" diaginertia="0.000430353 0.000429873 0.000164648"/>
                <joint name="left_wrist_pitch_joint" pos="0 0 0" axis="0 1 0" range="-1.61443 1.61443" actuatorfrcrange="-5 5"/>
                <geom type="mesh" contype="0" conaffinity="0" group="1" density="0" rgba="0.7 0.7 0.7 1" mesh="left_wrist_pitch_link"/>
                <geom type="mesh" rgba="0.7 0.7 0.7 1" mesh="left_wrist_pitch_link"/>
                <body name="left_wrist_yaw_link" pos="0.046 0 0">
                  <inertial pos="0.0708244 0.000191745 0.00161742" quat="0.510571 0.526295 0.468078 0.493188" mass="0.254576" diaginertia="0.000646113 0.000559993 0.000147566"/>
                  <joint name="left_wrist_yaw_joint" pos="0 0 0" axis="0 0 1" range="-1.61443 1.61443" actuatorfrcrange="-5 5"/>
                  <geom type="mesh" contype="0" conaffinity="0" group="1" density="0" rgba="0.7 0.7 0.7 1" mesh="left_wrist_yaw_link"/>
                  <geom type="mesh" rgba="0.7 0.7 0.7 1" mesh="left_wrist_yaw_link"/>
                  <include file="left_hand_attachement.xml"/>
                </body>
              </body>
            </body>
          </body>
        </body>
      </body>
    </body>

    <body name="right_shoulder_pitch_link" pos="-7.2e-06 -0.10021 0.29178" quat="0.990264 -0.139201 1.38722e-05 9.86868e-05">
      <inertial pos="0 -0.035892 -0.011628" quat="0.68225 -0.326267 0.0130458 0.654152" mass="0.718" diaginertia="0.000465864 0.000432842 0.000406394"/>
      <joint name="right_shoulder_pitch_joint" pos="0 0 0" axis="0 1 0" range="-3.0892 2.6704" actuatorfrcrange="-25 25"/>
      <geom type="mesh" contype="0" conaffinity="0" group="1" density="0" rgba="0.7 0.7 0.7 1" mesh="right_shoulder_pitch_link"/>
      <geom size="0.03 0.025" pos="0 -0.04 -0.01" quat="0.707107 0 0.707107 0" type="cylinder" rgba="0.7 0.7 0.7 1"/>
      <body name="right_shoulder_roll_link" pos="0 -0.038 -0.013831" quat="0.990268 0.139172 0 0">
        <inertial pos="-0.000227 -0.00727 -0.063243" quat="0.712604 -0.00710317 -0.0196223 0.701256" mass="0.643" diaginertia="0.000691311 0.000618011 0.000388977"/>
        <joint name="right_shoulder_roll_joint" pos="0 0 0" axis="1 0 0" range="-2.2515 1.5882" actuatorfrcrange="-25 25"/>
        <geom type="mesh" contype="0" conaffinity="0" group="1" density="0" rgba="0.7 0.7 0.7 1" mesh="right_shoulder_roll_link"/>
        <geom size="0.03 0.015" pos="-0.004 -0.006 -0.053" type="cylinder" rgba="0.7 0.7 0.7 1"/>
        <body name="right_shoulder_yaw_link" pos="0 -0.00624 -0.1032">
          <inertial pos="0.010773 0.002949 -0.072009" quat="0.687134 -0.0679942 -0.0964829 0.716879" mass="0.734" diaginertia="0.00106187 0.00103217 0.000400661"/>
          <joint name="right_shoulder_yaw_joint" pos="0 0 0" axis="0 0 1" range="-2.618 2.618" actuatorfrcrange="-25 25"/>
          <geom type="mesh" contype="0" conaffinity="0" group="1" density="0" rgba="0.7 0.7 0.7 1" mesh="right_shoulder_yaw_link"/>
          <geom type="mesh" rgba="0.7 0.7 0.7 1" mesh="right_shoulder_yaw_link"/>
          <body name="right_elbow_link" pos="0.015783 0 -0.080518">
            <inertial pos="0.064956 -0.004454 -0.010062" quat="0.388129 0.388821 0.636132 0.541765" mass="0.6" diaginertia="0.000443035 0.000421612 0.000259353"/>
            <joint name="right_elbow_joint" pos="0 0 0" axis="0 1 0" range="-1.0472 2.0944" actuatorfrcrange="-25 25"/>
            <geom type="mesh" contype="0" conaffinity="0" group="1" density="0" rgba="0.7 0.7 0.7 1" mesh="right_elbow_link"/>
            <geom type="mesh" rgba="0.7 0.7 0.7 1" mesh="right_elbow_link"/>
            <body name="right_wrist_roll_link" pos="0.1 -0.00188791 -0.01">
              <inertial pos="0.0171394 -0.000537591 4.8864e-07" quat="0.411667 0.575338 -0.411094 0.574906" mass="0.085445" diaginertia="5.48211e-05 4.96646e-05 3.57798e-05"/>
              <joint name="right_wrist_roll_joint" pos="0 0 0" axis="1 0 0" range="-1.97222 1.97222" actuatorfrcrange="-25 25"/>
              <geom type="mesh" contype="0" conaffinity="0" group="1" density="0" rgba="0.7 0.7 0.7 1" mesh="right_wrist_roll_link"/>
              <geom type="mesh" rgba="0.7 0.7 0.7 1" mesh="right_wrist_roll_link"/>
              <body name="right_wrist_pitch_link" pos="0.038 0 0">
                <inertial pos="0.0229999 0.00111685 -0.00111658" quat="0.643608 0.293036 0.661363 0.249998" mass="0.48405" diaginertia="0.000430353 0.000429873 0.000164648"/>
                <joint name="right_wrist_pitch_joint" pos="0 0 0" axis="0 1 0" range="-1.61443 1.61443" actuatorfrcrange="-5 5"/>
                <geom type="mesh" contype="0" conaffinity="0" group="1" density="0" rgba="0.7 0.7 0.7 1" mesh="right_wrist_pitch_link"/>
                <geom type="mesh" rgba="0.7 0.7 0.7 1" mesh="right_wrist_pitch_link"/>
                <body name="right_wrist_yaw_link" pos="0.046 0 0">
                  <inertial pos="0.0708244 -0.000191745 0.00161742" quat="0.493188 0.468078 0.526295 0.510571" mass="0.254576" diaginertia="0.000646113 0.000559993 0.000147566"/>
                  <joint name="right_wrist_yaw_joint" pos="0 0 0" axis="0 0 1" range="-1.61443 1.61443" actuatorfrcrange="-5 5"/>
                  <geom type="mesh" contype="0" conaffinity="0" group="1" density="0" rgba="0.7 0.7 0.7 1" mesh="right_wrist_yaw_link"/>
                  <geom type="mesh" rgba="0.7 0.7 0.7 1" mesh="right_wrist_yaw_link"/>
                  <geom pos="0.0415 -0.003 0" quat="1 0 0 0" type="mesh" contype="0" conaffinity="0" group="1" density="0" rgba="0.7 0.7 0.7 1" mesh="right_rubber_hand"/>
                </body>
              </body>
            </body>
          </body>
        </body>
      </body>
    </body>
  </worldbody>
<contact>
    <exclude body1="lh_thproximal" body2="lh_thmiddle"/>
  </contact>

  <tendon>
    <fixed name="lh_FFJ0">
      <joint joint="lh_FFJ2" coef="1"/>
      <joint joint="lh_FFJ1" coef="1"/>
    </fixed>
    <fixed name="lh_MFJ0">
      <joint joint="lh_MFJ2" coef="1"/>
      <joint joint="lh_MFJ1" coef="1"/>
    </fixed>
    <fixed name="lh_RFJ0">
      <joint joint="lh_RFJ2" coef="1"/>
      <joint joint="lh_RFJ1" coef="1"/>
    </fixed>
    <fixed name="lh_LFJ0">
      <joint joint="lh_LFJ2" coef="1"/>
      <joint joint="lh_LFJ1" coef="1"/>
    </fixed>
  </tendon>
  <actuator>
    <!-- Left Arm -->
    <position name="left_A_shoulder_pitch_joint" joint="left_shoulder_pitch_joint" class="arm_joint"/>
    <position name="left_A_shoulder_roll_joint"  joint="left_shoulder_roll_joint"  class="arm_joint"/>
    <position name="left_A_shoulder_yaw_joint"   joint="left_shoulder_yaw_joint"   class="arm_joint"/>
    <position name="left_A_elbow_joint"          joint="left_elbow_joint"          class="arm_joint"/>
    <position name="left_A_wrist_roll_joint"     joint="left_wrist_roll_joint"     class="arm_joint"/>
    <position name="left_A_wrist_pitch_joint"    joint="left_wrist_pitch_joint"    class="arm_joint"/>
    <position name="left_A_wrist_yaw_joint"      joint="left_wrist_yaw_joint"      class="arm_joint"/>

    <!-- Right Arm -->
    <position name="right_A_shoulder_pitch_joint" joint="right_shoulder_pitch_joint" class="arm_joint"/>
    <position name="right_A_shoulder_roll_joint"  joint="right_shoulder_roll_joint"  class="arm_joint"/>
    <position name="right_A_shoulder_yaw_joint"   joint="right_shoulder_yaw_joint"   class="arm_joint"/>
    <position name="right_A_elbow_joint"          joint="right_elbow_joint"          class="arm_joint"/>
    <position name="right_A_wrist_roll_joint"     joint="right_wrist_roll_joint"     class="arm_joint"/>
    <position name="right_A_wrist_pitch_joint"    joint="right_wrist_pitch_joint"    class="arm_joint"/>
    <position name="right_A_wrist_yaw_joint"      joint="right_wrist_yaw_joint"      class="arm_joint"/>

    
    <position name="lh_A_WRJ1" joint="lh_WRJ1" class="wrist_x"/>
    <position name="lh_A_THJ5" joint="lh_THJ5" class="thbase"/>
    <position name="lh_A_THJ4" joint="lh_THJ4" class="thproximal"/>
    <position name="lh_A_THJ3" joint="lh_THJ3" class="thhub"/>
    <position name="lh_A_THJ2" joint="lh_THJ2" class="thmiddle"/>
    <position name="lh_A_THJ1" joint="lh_THJ1" class="thdistal"/>
    <position name="lh_A_FFJ4" joint="lh_FFJ4" class="knuckle"/>
    <position name="lh_A_FFJ3" joint="lh_FFJ3" class="proximal"/>
    <position name="lh_A_FFJ0" tendon="lh_FFJ0" class="middle_distal"/>
    <position name="lh_A_MFJ4" joint="lh_MFJ4" class="knuckle"/>
    <position name="lh_A_MFJ3" joint="lh_MFJ3" class="proximal"/>
    <position name="lh_A_MFJ0" tendon="lh_MFJ0" class="middle_distal"/>
    <position name="lh_A_RFJ4" joint="lh_RFJ4" class="knuckle"/>
    <position name="lh_A_RFJ3" joint="lh_RFJ3" class="proximal"/>
    <position name="lh_A_RFJ0" tendon="lh_RFJ0" class="middle_distal"/>
    <position name="lh_A_LFJ5" joint="lh_LFJ5" class="metacarpal"/>
    <position name="lh_A_LFJ4" joint="lh_LFJ4" class="knuckle"/>
    <position name="lh_A_LFJ3" joint="lh_LFJ3" class="proximal"/>
    <position name="lh_A_LFJ0" tendon="lh_LFJ0" class="middle_distal"/>
  </actuator>

  <!-- setup scene -->
  <statistic center="1.0 0.7 1.0" extent="0.8"/>
  <visual>
    <headlight diffuse="0.6 0.6 0.6" ambient="0.1 0.1 0.1" specular="0.9 0.9 0.9"/>
    <rgba haze="0.15 0.25 0.35 1"/>
    <global azimuth="-140" elevation="-20"/>
  </visual>

  <asset>
    <texture type="skybox" builtin="flat" rgb1="0 0 0" rgb2="0 0 0" width="512" height="3072"/>
    <texture type="2d" name="groundplane" builtin="checker" mark="edge" rgb1="0.2 0.3 0.4" rgb2="0.1 0.2 0.3" markrgb="0.8 0.8 0.8" width="300" height="300"/>
    <material name="groundplane" texture="groundplane" texrepeat="300 300" reflectance="0.5"/>
  </asset>

  <worldbody>
  <light pos="1 0 3.5" dir="0 0 -1" directional="true"/>
    <geom name="floor" pos="0 0 0" size="5 5 0.1" type="plane" material="groundplane"/>
  </worldbody>
</mujoco>
